[2022-06-10 20:00:01,045]-[ERROR] [run_job - 131- Job "plane_update (trigger: interval[6:00:00], next run at: 2022-06-11 02:00:00 CST)" raised an exception]
Traceback (most recent call last):
  File "D:\Python3.10.4\lib\site-packages\apscheduler\executors\base.py", line 125, in run_job
    retval = job.func(*job.args, **job.kwargs)
  File "D:\民航行程推荐\wsgi.py", line 542, in plane_update
    Function.planes_Update_Function()  # 执行数据库更新函数
  File "D:\民航行程推荐\Function.py", line 133, in planes_Update_Function
    city, index, numbers = i
ValueError: not enough values to unpack (expected 3, got 2)
[2022-06-10 20:00:01,055]-[ERROR] [listen_error - 554- 数据库更新时出现了错误!]
[2022-06-11 02:00:01,034]-[ERROR] [run_job - 131- Job "plane_update (trigger: interval[6:00:00], next run at: 2022-06-11 08:00:00 CST)" raised an exception]
Traceback (most recent call last):
  File "D:\Python3.10.4\lib\site-packages\apscheduler\executors\base.py", line 125, in run_job
    retval = job.func(*job.args, **job.kwargs)
  File "D:\民航行程推荐\wsgi.py", line 542, in plane_update
    Function.planes_Update_Function()  # 执行数据库更新函数
  File "D:\民航行程推荐\Function.py", line 133, in planes_Update_Function
    city, index, numbers = i
ValueError: not enough values to unpack (expected 3, got 2)
[2022-06-11 02:00:01,034]-[ERROR] [listen_error - 554- 数据库更新时出现了错误!]
[2022-06-11 08:00:01,038]-[ERROR] [run_job - 131- Job "plane_update (trigger: interval[6:00:00], next run at: 2022-06-11 14:00:00 CST)" raised an exception]
Traceback (most recent call last):
  File "D:\Python3.10.4\lib\site-packages\apscheduler\executors\base.py", line 125, in run_job
    retval = job.func(*job.args, **job.kwargs)
  File "D:\民航行程推荐\wsgi.py", line 542, in plane_update
    Function.planes_Update_Function()  # 执行数据库更新函数
  File "D:\民航行程推荐\Function.py", line 133, in planes_Update_Function
    city, index, numbers = i
ValueError: not enough values to unpack (expected 3, got 2)
[2022-06-11 08:00:01,038]-[ERROR] [listen_error - 554- 数据库更新时出现了错误!]
[2022-06-11 14:00:01,023]-[ERROR] [run_job - 131- Job "plane_update (trigger: interval[6:00:00], next run at: 2022-06-11 20:00:00 CST)" raised an exception]
Traceback (most recent call last):
  File "D:\Python3.10.4\lib\site-packages\apscheduler\executors\base.py", line 125, in run_job
    retval = job.func(*job.args, **job.kwargs)
  File "D:\民航行程推荐\wsgi.py", line 542, in plane_update
    Function.planes_Update_Function()  # 执行数据库更新函数
  File "D:\民航行程推荐\Function.py", line 133, in planes_Update_Function
    city, index, numbers = i
ValueError: not enough values to unpack (expected 3, got 2)
[2022-06-11 14:00:01,023]-[ERROR] [listen_error - 554- 数据库更新时出现了错误!]
